<?xml version="1.0"?>

<robot name="dumpUrdf">


	<link name="base">
		<!-- <inertial>
			<origin rpy = "0 0 0" xyz = "0 0 0" />
			<mass value = "0.0001" />
			<inertia ixx = "0.0001" ixy = "0" ixz = "0" iyy = "0.0001" iyz = "0" izz = "0.0001" />
		</inertial> -->
	
	</link>
	
	<!-- Root  -->
	<link name="root">
		<inertial>
			<origin rpy = "0 0 0" xyz = "0.000000 0.070000 0.000000" />
			<mass value = "12.000000" />
			<inertia ixx = "0.03888" ixy = "0" ixz = "0" iyy = "0.03888" iyz = "0" izz = "0.03888" />
		</inertial>		
		<collision>
			<origin rpy = "0 0 0" xyz = "0.000000 0.070000 0.000000" />
			<geometry>
				<sphere radius = "0.090000" />
			</geometry>
		</collision>
		<visual>
			<origin rpy = "0 0 0" xyz = "0.000000 0.070000 0.000000" />
			<geometry>
				<sphere radius = "0.090000" />
			</geometry>
		</visual>
	</link>
	<joint name="root" type="fixed">
		<parent link="base" />
		<child link="root" />
		<origin rpy = "0 0 0" xyz = "0.000000 0.000000 0.0000" />
		<!-- <origin rpy = "1.570796 0 0" xyz = "0.000000 0.000000 0.870000" /> -->
	</joint>

	<!-- Chest  -->
	<link name="chest">
		<inertial>
			<origin rpy = "0 0 0" xyz = "0.000000 0.120000 0.000000" />
			<mass value = "28.000000" />
			<inertia ixx = "0.1552" ixy = "0" ixz = "0" iyy = "0.1552" iyz = "0" izz = "0.1552" />
		</inertial>
		<collision>
			<origin rpy = "0 0 0" xyz = "0.000000 0.120000 0.000000" />
			<geometry>
				<sphere radius = "0.110000" />
			</geometry>
		</collision>
		<visual>
			<origin rpy = "0 0 0" xyz = "0.000000 0.120000 0.000000" />
			<geometry>
				<sphere radius = "0.110000" />
			</geometry>
		</visual>
	</link>
	<joint name="chest" type="spherical">
		<parent link="root" />
		<child link="chest" />
		<origin rpy = "0 0 0" xyz = "0.000000 0.234 0.000000" />		
	</joint>


	<!-- Neck -->
	<link name="neck">
		<inertial>
			<origin rpy = "0 0 0" xyz = "0.000000 0.17500000 0.000000" />
			<mass value = "4.000000" />
			<inertia ixx = "0.0174" ixy = "0" ixz = "0" iyy = "0.0174" iyz = "0" izz = "0.0174" />
		</inertial>
		<collision>
			<origin rpy = "0 0 0" xyz = "0.000000 0.1750000 0.000000" />
			<geometry>
				<sphere radius = "0.1050000" />
			</geometry>
		</collision>
		<visual>
			<origin rpy = "0 0 0" xyz = "0.000000 0.17500000 0.000000" />
			<geometry>
				<sphere radius = "0.1050000" />
			</geometry>
		</visual>
	</link>
	<joint name="neck" type="spherical">
		<parent link="chest" />
		<child link="neck" />
		<origin rpy = "0 0 0" xyz = "0.000000 0.224 0.000000" />
	</joint>



	<!-- Right Hip -->
	<joint name="right_hip" type="spherical">
		<parent link="root" />
		<child link="right_hip" />
		<origin rpy="0 0 0" xyz="0 0 0.085" />
	</joint>

	<link name="right_hip">
		<inertial>
			<origin rpy = "0 0 0" xyz = "0.000000 -0.230000 0" />
			<mass value = "9.00000" />
			<inertia ixx = "0.126" ixy = "0" ixz = "0" iyy = "0.0138" iyz = "0" izz = "0.126" />
		</inertial>
		<collision>
			<origin rpy = "-1.570796 0 0" xyz = "0.000000 -0.240000 0.000000" />
			<geometry>
				<capsule length="0.1200000" radius="0.055000"/>
			</geometry>
		</collision>
		<visual>
			<origin rpy = "-1.570796 0 0" xyz = "0.000000 -0.240000 0.000000" />
			<geometry>
				<capsule length="0.1200000" radius="0.0550000"/>
			</geometry>			
		</visual>
	</link>

	<!-- Right Knee -->
	<link name="right_knee">
		<inertial>
			<origin rpy = "0 0 0" xyz = "0.000000 -0.210000 0.000000" />
			<mass value = "6.000000" />
			<inertia ixx = "0.0754" ixy = "0" ixz = "0" iyy = "0.007234" iyz = "0" izz = "0.0754" />
		</inertial>
		<collision>
			<origin rpy = "-1.570796 0 0" xyz = "0.000000 -0.210000 0.000000" />
			<geometry>
				<capsule length="0.120000" radius="0.0500000"/>
			</geometry>
		</collision>
		<visual>
			<origin rpy = "-1.570796 0 0" xyz = "0.000000 -0.210000 0.000000" />
			<geometry>
				<capsule length="0.12000" radius="0.0500000"/>
			</geometry>
		</visual>
	</link>
	<joint name="right_knee" type="revolute">
		<parent link="right_hip" />
		<child link="right_knee" />
		<origin rpy = "0 0 0" xyz = "0.000000 -0.4212 0.000000" />
		<limit effort="1000.0" lower="-3.14" upper="3.14" velocity="1.5"/>
		<axis xyz = "0.000000 0.000000 1.000000" />
	</joint>
	

	<!-- Right Ankle -->
	<link name="right_ankle">
		<inertial>
			<origin rpy = "0 0 0" xyz = "0.0450000 -0.02250000 0.000000" />
			<mass value = "2.000000" />
			<inertia ixx = "0.0018542" ixy = "0" ixz = "0" iyy = "0.006572" iyz = "0" izz = "0.00573" />
		</inertial>
		<collision>
			<origin rpy = "0 0 0" xyz = "0.0450000 -0.02250000 0.000000" />
			<geometry>
				<box size="0.177000 0.0550000 0.090000" />
			</geometry>
		</collision>
		<visual>
			<origin rpy = "0 0 0" xyz = "0.0450000 -0.02250000 0.000000" />
			<geometry>
				<box size="0.177000 0.0550000 0.090000" />
			</geometry>
		</visual>
	</link>
	<joint name="right_ankle" type="spherical">
		<parent link="right_knee" />
		<child link="right_ankle" />
		<origin rpy="0 0 0" xyz="0.000000 -0.4098 0.000000" />
	</joint>

	<!-- Right Shoulder -->
	<link name="right_shoulder">
		<inertial>
			<origin rpy = "0 0 0" xyz = "0.0000000 -0.14 0" /> 
			<mass value = "3.00000" />
			<inertia ixx = "0.0162" ixy = "0" ixz = "0" iyy = "0.002886" iyz = "0" izz = "0.0162" />
		</inertial>
		<collision>
			<origin rpy = "-1.570796 0 0" xyz = "0.000000 -0.140000 0.000000" />
			<geometry>
				<capsule length="0.090000" radius="0.0450000"/>
			</geometry>
		</collision>
		<visual>
			<origin rpy = "-1.570796 0 0" xyz = "0.000000 -0.140000 0.000000" />
			<geometry>
				<capsule length="0.090000" radius="0.0450000"/>
			</geometry>
		</visual>
	</link>
	<joint name="right_shoulder" type="spherical">
		<parent link="chest" />
		<child link="right_shoulder" />
		<origin rpy = "0 0 0" xyz = "-0.024 0.243 0.183" />
	</joint>


	<!-- Right Elbow -->
	<link name="right_elbow">
		<inertial>		
			<origin rpy = "0 0 0" xyz = "0.000000 -0.120000 0.000000" /> 
			<mass value = "2.000000" />
			<inertia ixx = "0.006904" ixy = "0" ixz = "0" iyy = "0.00159" iyz = "0" izz = "0.006904" />
		</inertial>
		<collision>
			<origin rpy = "-1.570796 0 0" xyz = "0.000000 -0.120000 0.000000" />
			<geometry>
				<capsule length="0.0680000" radius="0.040000"/>
			</geometry>
		</collision>
		<visual>
			<origin rpy = "-1.570796 0 0" xyz = "0.000000 -0.120000 0.000000" />
			<geometry>
				<capsule length="0.0680000" radius="0.040000"/>
			</geometry>			
		</visual>
	</link>
	<joint name="right_elbow" type="revolute">
		<parent link="right_shoulder" />
		<child link="right_elbow" />
		<limit effort="1000.0" lower="-3.14" upper="3.14" velocity="1.5"/>
		<origin rpy = "0 0 0" xyz = "0 -0.275 0 " />
		<axis xyz = "0.000000 0.000000 1.000000" />		
	</joint>

	<!-- Right Wrist -->
	<link name="right_wrist">
		<inertial>
			<origin rpy = "0 0 0" xyz = "0.000000 0.000000 0.000000" />
			<mass value = "1.00000" />
			<inertia ixx = "0.00064" ixy = "0" ixz = "0" iyy = "0.00064" iyz = "0" izz = "0.00064" />
		</inertial>
		<collision>
			<origin rpy = "0 0 0" xyz = "0.000000 0.000000 0.000000" />
			<geometry>
				<sphere radius = "0.040000" />
			</geometry>
		</collision>
		<visual>
			<origin rpy = "0 0 0" xyz = "0.000000 0.000000 0.000000" />
			<geometry>
				<sphere radius = "0.040000" />
			</geometry>
		</visual>
	</link>
	<joint name="right_wrist" type="fixed">
		<parent link="right_elbow" />
		<child link="right_wrist" />
		<origin rpy = "0 0 0" xyz = "0.000000 -0.26 0.000000" />
	</joint>

	<!-- Left Hip -->
	<link name="left_hip">
		<inertial>
			<origin rpy = "0 0 0" xyz = "0.000000 -0.230000 0.000000" />
			<mass value = "9.00000" />
			<inertia ixx = "0.126" ixy = "0" ixz = "0" iyy = "0.0138" iyz = "0" izz = "0.126" />
		</inertial>
		<collision>
			<origin rpy = "-1.570796 0 0" xyz = "0.000000 -0.240000 0.000000" />
			<geometry>
				<capsule length="0.1200000" radius="0.0550000"/>
			</geometry>
		</collision>
		<visual>
			<origin rpy = "-1.570796 0 0" xyz = "0.000000 -0.240000 0.000000" />
			<geometry>
				<capsule length="0.120000" radius="0.0550000"/>
			</geometry>
		</visual>
	</link>
	<joint name="left_hip" type="spherical">
		<parent link="root" />
		<child link="left_hip" />
		<origin rpy = "0 0 0" xyz = "0.000000 0.0000 -0.085" />  
		<dynamics damping="0.0" friction="0.0" />
	</joint>

	<!-- Left Knee -->
	<link name="left_knee">
		<inertial>
			<origin rpy = "0 0 0" xyz = "0.000000 -0.210000 0.000000" />
			<mass value = "6.000000" />
			<inertia ixx = "0.0754" ixy = "0" ixz = "0" iyy = "0.007234" iyz = "0" izz = "0.0754" />
		</inertial>
		<collision>
			<origin rpy = "-1.570796 0 0" xyz = "0.000000 -0.210000 0.000000" />
			<geometry>
				<capsule length="0.120000" radius="0.0500000"/>
			</geometry>
		</collision>
		<visual>
			<origin rpy = "-1.570796 0 0" xyz = "0.000000 -0.210000 0.000000" />
			<geometry>
				<capsule length="0.1200000" radius="0.0500000"/>
			</geometry>
		</visual>
	</link>
	<joint name="left_knee" type="revolute">
		<parent link="left_hip" />
		<child link="left_knee" />
		<origin rpy = "0 0 0" xyz = "0.000000 -0.4212 0.000000" />
		<limit effort="1000.0" lower="-3.14" upper="3.14" velocity="1.5"/>
		<axis xyz = "0.000000 0.000000 1.000000" />
	</joint>

	<!-- Left Ankle -->
	<link name="left_ankle">
		<inertial>
			<origin rpy = "0 0 0" xyz = "0.0450000 -0.02250000 0.000000" />
			<mass value = "2.000000" />
			<inertia ixx = "0.0018542" ixy = "0" ixz = "0" iyy = "0.006572" iyz = "0" izz = "0.00573" />
		</inertial>
		<collision>
			<origin rpy = "0 0 0" xyz = "0.0450000 -0.02250000 0.000000" />
			<geometry>
				<box size="0.177000 0.0550000 0.090000" />
			</geometry>
		</collision>
		<visual>
			<origin rpy = "0 0 0" xyz = "0.0450000 -0.02250000 0.000000" />
			<geometry>
				<box size="0.177000 0.0550000 0.090000" />
			</geometry>
		</visual>
	</link>
	<joint name="left_ankle" type="spherical">
		<parent link="left_knee" />
		<child link="left_ankle" />
		<origin rpy = "0 0 0" xyz = "0.000000 -0.4098 0.000000" />
		<dynamics damping="0.0" friction="0.0" />
	</joint>

	<!-- Left Shoulder -->
	<link name="left_shoulder">
		<inertial>
			<origin rpy = "0 0 0" xyz = "0.000000 -0.14 0" />
			<mass value = "3.00000" />
			<inertia ixx = "0.0162" ixy = "0" ixz = "0" iyy = "0.002886" iyz = "0" izz = "0.0162" />
		</inertial>
		<collision>
			<origin rpy = "-1.570796 0 0" xyz = "0.000000 -0.140000 0.000000" />
			<geometry>
				<capsule length="0.090000" radius="0.0450000"/>
			</geometry>
		</collision>
		<visual>
			<origin rpy = "-1.570796 0 0" xyz = "0.000000 -0.140000 0.000000" />
			<geometry>
				<capsule length="0.090000" radius="0.0450000"/>
			</geometry>
		</visual>
	</link>
	<joint name="left_shoulder" type="spherical">
		<parent link="chest" />
		<child link="left_shoulder" />
		<origin rpy = "0 0 0" xyz = "-0.024 0.243 -0.183" />
	</joint>

	<!-- Left Elbow -->
	<link name="left_elbow">
		<inertial>
			<origin rpy = "0 0 0" xyz = "0.000000 -0.120000 0.000000" />
			<mass value = "2.000000" />
			<inertia ixx = "0.006904" ixy = "0" ixz = "0" iyy = "0.00159" iyz = "0" izz = "0.006904" />
		</inertial>
		<collision>
			<origin rpy = "-1.570796 0 0" xyz = "0.000000 -0.120000 0.000000" />
			<geometry>
				<capsule length="0.0680000" radius="0.040000"/>
			</geometry>
		</collision>
		<visual>
			<origin rpy = "-1.570796 0 0" xyz = "0.000000 -0.120000 0.000000" />
			<geometry>
				<capsule length="0.0680000" radius="0.040000"/>
			</geometry>
		</visual>
	</link>
	<joint name="left_elbow" type="revolute">
		<parent link="left_shoulder" />
		<child link="left_elbow" />
		<limit effort="1000.0" lower="-3.14" upper="3.14" velocity="0.5"/>
		<origin rpy = "0 0 0" xyz = "0.000000 -0.275 0.000000" />
		<axis xyz = "0.000000 0.000000 1.000000" />
		<dynamics damping="0.0" friction="0.0" />
	</joint>

	<!-- Left Wrist -->
	<link name="left_wrist">
		<inertial>
			<origin rpy = "0 0 0" xyz = "0.000000 0.000000 0.000000" />
			<mass value = "1.00000" />
			<inertia ixx = "0.00064" ixy = "0" ixz = "0" iyy = "0.00064" iyz = "0" izz = "0.00064" />
		</inertial>
		<collision>
			<origin rpy = "0 0 0" xyz = "0.000000 0.000000 0.000000" />
			<geometry>
				<sphere radius = "0.040000" />
			</geometry>
		</collision>
		<visual>
			<origin rpy = "0 0 0" xyz = "0.000000 0.000000 0.000000" />
			<geometry>
				<sphere radius = "0.040000" />
			</geometry>
		</visual>
	</link>
	<joint name="left_wrist" type="fixed">
		<parent link="left_elbow" />
		<child link="left_wrist" />
		<origin rpy = "0 0 0" xyz = "0.000000 -0.26 0.000000" />
	</joint>
</robot>